WARNING:tornado.access:405 CONNECT mx0.mail2000.com.tw:25 (1.171.76.167) 7.03ms
WARNING:tornado.access:405 CONNECT mx3.mail2000.com.tw:25 (36.226.115.224) 6.66ms
WARNING:tornado.access:404 GET /favicon.ico (81.45.53.235) 6.05ms
WARNING:tornado.access:404 GET /favicon.ico (81.45.53.235) 6.23ms
WARNING:tornado.access:404 GET http://www.ly.com/ (182.254.158.222) 6.88ms
WARNING:tornado.access:405 CONNECT mx3.mail2000.com.tw:25 (118.165.129.57) 6.65ms
WARNING:tornado.access:404 GET /tmUnblock.cgi (203.128.72.202) 6.08ms
  File "/home/pi/M2More/services.py", line 23
    invalid_data = cur.execute(select count(*) from log where data = 0)
                                          ^
SyntaxError: invalid syntax
  File "/home/pi/M2More/services.py", line 23
    invalid_data = cur.execute(select count(*) from log where data = 0)
                                          ^
SyntaxError: invalid syntax
  File "/home/pi/M2More/services.py", line 23
    invalid_data = cur.execute(select count(*) from log where data = 0)
                                          ^
SyntaxError: invalid syntax
  File "/home/pi/M2More/services.py", line 23
    invalid_data = cur.execute(select count(*) from log where data = 0)
                                          ^
SyntaxError: invalid syntax
  File "/home/pi/M2More/services.py", line 23
    invalid_data = cur.execute(select count(*) from log where data = 0)
                                          ^
SyntaxError: invalid syntax
  File "/home/pi/M2More/services.py", line 23
    invalid_data = cur.execute(select count(*) from log where data = 0)
                                          ^
SyntaxError: invalid syntax
  File "/home/pi/M2More/services.py", line 23
    invalid_data = cur.execute(select count(*) from log where data = 0)
                                          ^
SyntaxError: invalid syntax
  File "/home/pi/M2More/services.py", line 23
    invalid_data = cur.execute(select count(*) from log where data = 0)
                                          ^
SyntaxError: invalid syntax
  File "/home/pi/M2More/services.py", line 23
    invalid_data = cur.execute(select count(*) from log where data = 0)
                                          ^
SyntaxError: invalid syntax
  File "/home/pi/M2More/services.py", line 23
    invalid_data = cur.execute(select count(*) from log where data = 0)
                                          ^
SyntaxError: invalid syntax
  File "/home/pi/M2More/services.py", line 23
    invalid_data = cur.execute(select count(*) from log where data = 0)
                                          ^
SyntaxError: invalid syntax
WARNING:tornado.access:404 GET /favicon.ico (192.168.1.35) 6.59ms
ERROR:tornado.application:Uncaught exception GET /statistics (192.168.1.35)
HTTPServerRequest(protocol='http', host='192.168.1.50', method='GET', uri='/statistics', version='HTTP/1.1', remote_ip='192.168.1.35', headers={'Connection': 'keep-alive', 'Accept-Language': 'en-US,en;q=0.8,es;q=0.6', 'Accept-Encoding': 'gzip, deflate, sdch', 'Host': '192.168.1.50', 'Accept': 'text/html,application/xhtml+xml,application/xml;q=0.9,image/webp,*/*;q=0.8', 'User-Agent': 'Mozilla/5.0 (Windows NT 6.1) AppleWebKit/537.36 (KHTML, like Gecko) Chrome/39.0.2171.95 Safari/537.36'})
Traceback (most recent call last):
  File "/usr/local/lib/python2.7/dist-packages/tornado/web.py", line 1332, in _execute
    result = method(*self.path_args, **self.path_kwargs)
  File "/home/pi/M2More/services.py", line 21, in get
    with con:
NameError: global name 'con' is not defined
ERROR:tornado.access:500 GET /statistics (192.168.1.35) 28.97ms
ERROR:tornado.application:Uncaught exception GET /statistics (192.168.1.35)
HTTPServerRequest(protocol='http', host='192.168.1.50', method='GET', uri='/statistics', version='HTTP/1.1', remote_ip='192.168.1.35', headers={'Connection': 'keep-alive', 'Accept-Language': 'en-US,en;q=0.8,es;q=0.6', 'Accept-Encoding': 'gzip, deflate, sdch', 'Cache-Control': 'max-age=0', 'Host': '192.168.1.50', 'Accept': 'text/html,application/xhtml+xml,application/xml;q=0.9,image/webp,*/*;q=0.8', 'User-Agent': 'Mozilla/5.0 (Windows NT 6.1) AppleWebKit/537.36 (KHTML, like Gecko) Chrome/39.0.2171.95 Safari/537.36'})
Traceback (most recent call last):
  File "/usr/local/lib/python2.7/dist-packages/tornado/web.py", line 1332, in _execute
    result = method(*self.path_args, **self.path_kwargs)
  File "/home/pi/M2More/services.py", line 26, in get
    self.write("<p>Statistics</p><p>" + invalid_data  + " - " + valid_data  + "</p>")
TypeError: cannot concatenate 'str' and 'long' objects
ERROR:tornado.access:500 GET /statistics (192.168.1.35) 253.68ms
ERROR:tornado.application:Uncaught exception GET /statistics (192.168.1.35)
HTTPServerRequest(protocol='http', host='192.168.1.50', method='GET', uri='/statistics', version='HTTP/1.1', remote_ip='192.168.1.35', headers={'Connection': 'keep-alive', 'Accept-Language': 'en-US,en;q=0.8,es;q=0.6', 'Accept-Encoding': 'gzip, deflate, sdch', 'Cache-Control': 'max-age=0', 'Host': '192.168.1.50', 'Accept': 'text/html,application/xhtml+xml,application/xml;q=0.9,image/webp,*/*;q=0.8', 'User-Agent': 'Mozilla/5.0 (Windows NT 6.1) AppleWebKit/537.36 (KHTML, like Gecko) Chrome/39.0.2171.95 Safari/537.36'})
Traceback (most recent call last):
  File "/usr/local/lib/python2.7/dist-packages/tornado/web.py", line 1332, in _execute
    result = method(*self.path_args, **self.path_kwargs)
  File "/home/pi/M2More/services.py", line 26, in get
    self.write("<p>Statistics</p><p>" + invalid_data  + " - " + valid_data  + "</p>")
TypeError: cannot concatenate 'str' and 'long' objects
ERROR:tornado.access:500 GET /statistics (192.168.1.35) 20.41ms
ERROR:tornado.application:Uncaught exception GET /statistics (192.168.1.35)
HTTPServerRequest(protocol='http', host='192.168.1.50', method='GET', uri='/statistics', version='HTTP/1.1', remote_ip='192.168.1.35', headers={'Connection': 'keep-alive', 'Accept-Language': 'en-US,en;q=0.8,es;q=0.6', 'Accept-Encoding': 'gzip, deflate, sdch', 'Cache-Control': 'max-age=0', 'Host': '192.168.1.50', 'Accept': 'text/html,application/xhtml+xml,application/xml;q=0.9,image/webp,*/*;q=0.8', 'User-Agent': 'Mozilla/5.0 (Windows NT 6.1) AppleWebKit/537.36 (KHTML, like Gecko) Chrome/39.0.2171.95 Safari/537.36'})
Traceback (most recent call last):
  File "/usr/local/lib/python2.7/dist-packages/tornado/web.py", line 1332, in _execute
    result = method(*self.path_args, **self.path_kwargs)
  File "/home/pi/M2More/services.py", line 26, in get
    self.write("<p>Statistics</p><p>" + invalid_data  + " - " + valid_data  + "</p>")
TypeError: cannot concatenate 'str' and 'long' objects
ERROR:tornado.access:500 GET /statistics (192.168.1.35) 20.51ms
WARNING:tornado.access:404 HEAD /robots.txt (81.38.212.120) 6.85ms
WARNING:tornado.access:404 GET /aiai/aia/ai.php (123.57.78.112) 6.94ms
WARNING:tornado.access:404 GET /phpMyAdmin/scripts/setup.php (123.57.78.112) 6.58ms
WARNING:tornado.access:404 HEAD /robots.txt (81.38.212.120) 6.52ms
WARNING:tornado.access:404 GET /tmUnblock.cgi (176.118.77.178) 6.15ms
WARNING:tornado.access:404 GET /favicon.ico (192.168.1.33) 6.25ms
WARNING:tornado.access:404 GET /stastistics (192.168.1.33) 6.16ms
WARNING:tornado.access:404 GET /stastistic (192.168.1.33) 6.26ms
ERROR:tornado.application:Uncaught exception GET /statistics (192.168.1.35)
HTTPServerRequest(protocol='http', host='192.168.1.50', method='GET', uri='/statistics', version='HTTP/1.1', remote_ip='192.168.1.35', headers={'Connection': 'keep-alive', 'Accept-Language': 'en-US,en;q=0.8,es;q=0.6', 'Accept-Encoding': 'gzip, deflate, sdch', 'If-None-Match': '"95f74fd06af8588feb3be68920163af6aa915195"', 'Host': '192.168.1.50', 'Accept': 'text/html,application/xhtml+xml,application/xml;q=0.9,image/webp,*/*;q=0.8', 'User-Agent': 'Mozilla/5.0 (Windows NT 6.1) AppleWebKit/537.36 (KHTML, like Gecko) Chrome/39.0.2171.95 Safari/537.36'})
Traceback (most recent call last):
  File "/usr/local/lib/python2.7/dist-packages/tornado/web.py", line 1332, in _execute
    result = method(*self.path_args, **self.path_kwargs)
  File "/home/pi/M2More/services.py", line 25, in get
    invalids_number = invalids.fetchone()
AttributeError: 'long' object has no attribute 'fetchone'
ERROR:tornado.access:500 GET /statistics (192.168.1.35) 197.92ms
WARNING:tornado.access:404 GET /favicon.ico (192.168.1.35) 6.62ms
ERROR:tornado.application:Uncaught exception GET /statistics (192.168.1.35)
HTTPServerRequest(protocol='http', host='192.168.1.50', method='GET', uri='/statistics', version='HTTP/1.1', remote_ip='192.168.1.35', headers={'Connection': 'keep-alive', 'Accept-Language': 'en-US,en;q=0.8,es;q=0.6', 'Accept-Encoding': 'gzip, deflate, sdch', 'Cache-Control': 'max-age=0', 'Host': '192.168.1.50', 'Accept': 'text/html,application/xhtml+xml,application/xml;q=0.9,image/webp,*/*;q=0.8', 'User-Agent': 'Mozilla/5.0 (Windows NT 6.1) AppleWebKit/537.36 (KHTML, like Gecko) Chrome/39.0.2171.95 Safari/537.36'})
Traceback (most recent call last):
  File "/usr/local/lib/python2.7/dist-packages/tornado/web.py", line 1332, in _execute
    result = method(*self.path_args, **self.path_kwargs)
  File "/home/pi/M2More/services.py", line 28, in get
    self.write("<p>Statistics</p><p>" + valids_number  + " - " + invalids_number  + "</p>")
TypeError: cannot concatenate 'str' and 'tuple' objects
ERROR:tornado.access:500 GET /statistics (192.168.1.35) 199.47ms
ERROR:tornado.application:Uncaught exception GET /statistics (192.168.1.35)
HTTPServerRequest(protocol='http', host='192.168.1.50', method='GET', uri='/statistics', version='HTTP/1.1', remote_ip='192.168.1.35', headers={'Connection': 'keep-alive', 'Accept-Language': 'en-US,en;q=0.8,es;q=0.6', 'Accept-Encoding': 'gzip, deflate, sdch', 'Cache-Control': 'max-age=0', 'Host': '192.168.1.50', 'Accept': 'text/html,application/xhtml+xml,application/xml;q=0.9,image/webp,*/*;q=0.8', 'User-Agent': 'Mozilla/5.0 (Windows NT 6.1) AppleWebKit/537.36 (KHTML, like Gecko) Chrome/39.0.2171.95 Safari/537.36'})
Traceback (most recent call last):
  File "/usr/local/lib/python2.7/dist-packages/tornado/web.py", line 1332, in _execute
    result = method(*self.path_args, **self.path_kwargs)
  File "/home/pi/M2More/services.py", line 28, in get
    self.write("<p>Statistics</p><p>" + valids_number  + " - " + invalids_number  + "</p>")
TypeError: cannot concatenate 'str' and 'tuple' objects
ERROR:tornado.access:500 GET /statistics (192.168.1.35) 21.90ms
ERROR:tornado.application:Uncaught exception GET /statistics (192.168.1.35)
HTTPServerRequest(protocol='http', host='192.168.1.50', method='GET', uri='/statistics', version='HTTP/1.1', remote_ip='192.168.1.35', headers={'Accept-Language': 'en-US,en;q=0.8,es;q=0.6', 'Accept-Encoding': 'gzip, deflate, sdch', 'Host': '192.168.1.50', 'Accept': 'text/html,application/xhtml+xml,application/xml;q=0.9,image/webp,*/*;q=0.8', 'User-Agent': 'Mozilla/5.0 (Windows NT 6.1) AppleWebKit/537.36 (KHTML, like Gecko) Chrome/39.0.2171.95 Safari/537.36', 'Connection': 'keep-alive', 'Cache-Control': 'max-age=0', 'If-None-Match': '"db91b877bf43cc4d731ec241061b5522150ed575"'})
Traceback (most recent call last):
  File "/usr/local/lib/python2.7/dist-packages/tornado/web.py", line 1332, in _execute
    result = method(*self.path_args, **self.path_kwargs)
  File "/home/pi/M2More/services.py", line 28, in get
    self.write("<p>Statistics</p><p>" + valids_number[0]  + " - " + invalids_number[0]  + "</p>")
TypeError: cannot concatenate 'str' and 'long' objects
ERROR:tornado.access:500 GET /statistics (192.168.1.35) 203.68ms
ERROR:tornado.application:Uncaught exception GET /statistics (192.168.1.35)
HTTPServerRequest(protocol='http', host='192.168.1.50', method='GET', uri='/statistics', version='HTTP/1.1', remote_ip='192.168.1.35', headers={'Connection': 'keep-alive', 'Accept-Language': 'en-US,en;q=0.8,es;q=0.6', 'Accept-Encoding': 'gzip, deflate, sdch', 'Cache-Control': 'max-age=0', 'Host': '192.168.1.50', 'Accept': 'text/html,application/xhtml+xml,application/xml;q=0.9,image/webp,*/*;q=0.8', 'User-Agent': 'Mozilla/5.0 (Windows NT 6.1) AppleWebKit/537.36 (KHTML, like Gecko) Chrome/39.0.2171.95 Safari/537.36'})
Traceback (most recent call last):
  File "/usr/local/lib/python2.7/dist-packages/tornado/web.py", line 1332, in _execute
    result = method(*self.path_args, **self.path_kwargs)
  File "/home/pi/M2More/services.py", line 28, in get
    self.write("<p>Statistics</p><p>" + valids_number[0]  + " - " + invalids_number[0]  + "</p>")
TypeError: cannot concatenate 'str' and 'long' objects
ERROR:tornado.access:500 GET /statistics (192.168.1.35) 22.03ms
ERROR:tornado.application:Uncaught exception GET /statistics (192.168.1.35)
HTTPServerRequest(protocol='http', host='192.168.1.50', method='GET', uri='/statistics', version='HTTP/1.1', remote_ip='192.168.1.35', headers={'Connection': 'keep-alive', 'Accept-Language': 'en-US,en;q=0.8,es;q=0.6', 'Accept-Encoding': 'gzip, deflate, sdch', 'Cache-Control': 'max-age=0', 'Host': '192.168.1.50', 'Accept': 'text/html,application/xhtml+xml,application/xml;q=0.9,image/webp,*/*;q=0.8', 'User-Agent': 'Mozilla/5.0 (Windows NT 6.1) AppleWebKit/537.36 (KHTML, like Gecko) Chrome/39.0.2171.95 Safari/537.36'})
Traceback (most recent call last):
  File "/usr/local/lib/python2.7/dist-packages/tornado/web.py", line 1332, in _execute
    result = method(*self.path_args, **self.path_kwargs)
  File "/home/pi/M2More/services.py", line 28, in get
    self.write("<p>Statistics</p><p>" + int(valids_number[0])  + " - " + int(invalids_number[0])  + "</p>")
TypeError: cannot concatenate 'str' and 'int' objects
ERROR:tornado.access:500 GET /statistics (192.168.1.35) 212.48ms
ERROR:tornado.application:Uncaught exception GET /statistics (192.168.1.35)
HTTPServerRequest(protocol='http', host='192.168.1.50', method='GET', uri='/statistics', version='HTTP/1.1', remote_ip='192.168.1.35', headers={'Connection': 'keep-alive', 'Accept-Language': 'en-US,en;q=0.8,es;q=0.6', 'Accept-Encoding': 'gzip, deflate, sdch', 'Cache-Control': 'max-age=0', 'Host': '192.168.1.50', 'Accept': 'text/html,application/xhtml+xml,application/xml;q=0.9,image/webp,*/*;q=0.8', 'User-Agent': 'Mozilla/5.0 (Windows NT 6.1) AppleWebKit/537.36 (KHTML, like Gecko) Chrome/39.0.2171.95 Safari/537.36'})
Traceback (most recent call last):
  File "/usr/local/lib/python2.7/dist-packages/tornado/web.py", line 1332, in _execute
    result = method(*self.path_args, **self.path_kwargs)
  File "/home/pi/M2More/services.py", line 28, in get
    self.write("<p>Statistics</p><p>" + int(valids_number[0])  + " - " + int(invalids_number[0])  + "</p>")
TypeError: cannot concatenate 'str' and 'int' objects
ERROR:tornado.access:500 GET /statistics (192.168.1.35) 37.95ms
ERROR:tornado.application:Uncaught exception GET /statistics (192.168.1.35)
HTTPServerRequest(protocol='http', host='192.168.1.50', method='GET', uri='/statistics', version='HTTP/1.1', remote_ip='192.168.1.35', headers={'Accept-Language': 'en-US,en;q=0.8,es;q=0.6', 'Accept-Encoding': 'gzip, deflate, sdch', 'Host': '192.168.1.50', 'Accept': 'text/html,application/xhtml+xml,application/xml;q=0.9,image/webp,*/*;q=0.8', 'User-Agent': 'Mozilla/5.0 (Windows NT 6.1) AppleWebKit/537.36 (KHTML, like Gecko) Chrome/39.0.2171.95 Safari/537.36', 'Connection': 'keep-alive', 'Cache-Control': 'max-age=0', 'If-None-Match': '"c96ac0f6bf5f2872c203caa4592161c21a4476c3"'})
Traceback (most recent call last):
  File "/usr/local/lib/python2.7/dist-packages/tornado/web.py", line 1332, in _execute
    result = method(*self.path_args, **self.path_kwargs)
  File "/home/pi/M2More/services.py", line 32, in get
    self.write("<p>Statistics</p><p>Valid data: " + valids_percent  + " %</p><p>Invalid data: " + invalids_percent  + " %</p>")
TypeError: cannot concatenate 'str' and 'int' objects
ERROR:tornado.access:500 GET /statistics (192.168.1.35) 204.20ms
ERROR:tornado.application:Uncaught exception GET /statistics (192.168.1.35)
HTTPServerRequest(protocol='http', host='192.168.1.50', method='GET', uri='/statistics', version='HTTP/1.1', remote_ip='192.168.1.35', headers={'Accept-Language': 'en-US,en;q=0.8,es;q=0.6', 'Accept-Encoding': 'gzip, deflate, sdch', 'Host': '192.168.1.50', 'Accept': 'text/html,application/xhtml+xml,application/xml;q=0.9,image/webp,*/*;q=0.8', 'User-Agent': 'Mozilla/5.0 (Windows NT 6.1) AppleWebKit/537.36 (KHTML, like Gecko) Chrome/39.0.2171.95 Safari/537.36', 'Connection': 'keep-alive', 'Cache-Control': 'max-age=0', 'If-None-Match': '"ea62d3d6fd8783dbe82c1344ca0e4ba973a36136"'})
Traceback (most recent call last):
  File "/usr/local/lib/python2.7/dist-packages/tornado/web.py", line 1332, in _execute
    result = method(*self.path_args, **self.path_kwargs)
  File "/home/pi/M2More/services.py", line 33, in get
    self.write("<p>Statistics</p><p>Valid data: " + valids_percent  + " %</p><p>Invalid data: " + invalids_percent  + " %</p>")
TypeError: cannot concatenate 'str' and 'float' objects
ERROR:tornado.access:500 GET /statistics (192.168.1.35) 205.91ms
ERROR:tornado.application:Uncaught exception GET /statistics (192.168.1.35)
HTTPServerRequest(protocol='http', host='192.168.1.50', method='GET', uri='/statistics', version='HTTP/1.1', remote_ip='192.168.1.35', headers={'Connection': 'keep-alive', 'Accept-Language': 'en-US,en;q=0.8,es;q=0.6', 'Accept-Encoding': 'gzip, deflate, sdch', 'Cache-Control': 'max-age=0', 'Host': '192.168.1.50', 'Accept': 'text/html,application/xhtml+xml,application/xml;q=0.9,image/webp,*/*;q=0.8', 'User-Agent': 'Mozilla/5.0 (Windows NT 6.1) AppleWebKit/537.36 (KHTML, like Gecko) Chrome/39.0.2171.95 Safari/537.36'})
Traceback (most recent call last):
  File "/usr/local/lib/python2.7/dist-packages/tornado/web.py", line 1332, in _execute
    result = method(*self.path_args, **self.path_kwargs)
  File "/home/pi/M2More/services.py", line 33, in get
    self.write("<p>Statistics</p><p>Valid data: " + valids_percent  + " %</p><p>Invalid data: " + invalids_percent  + " %</p>")
TypeError: cannot concatenate 'str' and 'float' objects
ERROR:tornado.access:500 GET /statistics (192.168.1.35) 21.26ms
  File "/home/pi/M2More/services.py", line 30
    valids_percent = (float(valids_number[0]) / float(rows_number[0])) * 100)
                                                                            ^
SyntaxError: invalid syntax
  File "/home/pi/M2More/services.py", line 30
    valids_percent = (float(valids_number[0]) / float(rows_number[0])) * 100)
                                                                            ^
SyntaxError: invalid syntax
  File "/home/pi/M2More/services.py", line 30
    valids_percent = (float(valids_number[0]) / float(rows_number[0])) * 100)
                                                                            ^
SyntaxError: invalid syntax
  File "/home/pi/M2More/services.py", line 30
    valids_percent = (float(valids_number[0]) / float(rows_number[0])) * 100)
                                                                            ^
SyntaxError: invalid syntax
  File "/home/pi/M2More/services.py", line 30
    valids_percent = (float(valids_number[0]) / float(rows_number[0])) * 100)
                                                                            ^
SyntaxError: invalid syntax
  File "/home/pi/M2More/services.py", line 30
    valids_percent = (float(valids_number[0]) / float(rows_number[0])) * 100)
                                                                            ^
SyntaxError: invalid syntax
  File "/home/pi/M2More/services.py", line 30
    valids_percent = (float(valids_number[0]) / float(rows_number[0])) * 100)
                                                                            ^
SyntaxError: invalid syntax
  File "/home/pi/M2More/services.py", line 30
    valids_percent = (float(valids_number[0]) / float(rows_number[0])) * 100)
                                                                            ^
SyntaxError: invalid syntax
ERROR:tornado.application:Uncaught exception GET /statistics (192.168.1.35)
HTTPServerRequest(protocol='http', host='192.168.1.50', method='GET', uri='/statistics', version='HTTP/1.1', remote_ip='192.168.1.35', headers={'Accept-Language': 'en-US,en;q=0.8,es;q=0.6', 'Accept-Encoding': 'gzip, deflate, sdch', 'Host': '192.168.1.50', 'Accept': 'text/html,application/xhtml+xml,application/xml;q=0.9,image/webp,*/*;q=0.8', 'User-Agent': 'Mozilla/5.0 (Windows NT 6.1) AppleWebKit/537.36 (KHTML, like Gecko) Chrome/39.0.2171.95 Safari/537.36', 'Connection': 'keep-alive', 'Cache-Control': 'max-age=0', 'If-None-Match': '"f3c76917628726adfc66dfd28ec325ca1a8179a4"'})
Traceback (most recent call last):
  File "/usr/local/lib/python2.7/dist-packages/tornado/web.py", line 1332, in _execute
    result = method(*self.path_args, **self.path_kwargs)
  File "/home/pi/M2More/services.py", line 34, in get
    self.write(statistics_dict)
  File "/usr/local/lib/python2.7/dist-packages/tornado/web.py", line 656, in write
    raise TypeError("write() only accepts bytes, unicode, and dict objects")
TypeError: write() only accepts bytes, unicode, and dict objects
ERROR:tornado.access:500 GET /statistics (192.168.1.35) 207.35ms
WARNING:tornado.access:404 GET http://s1.bdstatic.com/r/www/cache/static/home/img/logos/nuomi_ade5465d.png (125.64.35.68) 6.32ms
WARNING:tornado.access:404 GET http://s1.bdstatic.com/r/www/cache/static/home/img/logos/nuomi_ade5465d.png (125.64.35.67) 6.29ms
WARNING:tornado.access:404 POST //%63%67%69%2D%62%69%6E/%70%68%70?%2D%64+%61%6C%6C%6F%77%5F%75%72%6C%5F%69%6E%63%6C%75%64%65%3D%6F%6E+%2D%64+%73%61%66%65%5F%6D%6F%64%65%3D%6F%66%66+%2D%64+%73%75%68%6F%73%69%6E%2E%73%69%6D%75%6C%61%74%69%6F%6E%3D%6F%6E+%2D%64+%64%69%73%61%62%6C%65%5F%66%75%6E%63%74%69%6F%6E%73%3D%22%22+%2D%64+%6F%70%65%6E%5F%62%61%73%65%64%69%72%3D%6E%6F%6E%65+%2D%64+%61%75%74%6F%5F%70%72%65%70%65%6E%64%5F%66%69%6C%65%3D%70%68%70%3A%2F%2F%69%6E%70%75%74+%2D%64+%63%67%69%2E%66%6F%72%63%65%5F%72%65%64%69%72%65%63%74%3D%30+%2D%64+%63%67%69%2E%72%65%64%69%72%65%63%74%5F%73%74%61%74%75%73%5F%65%6E%76%3D%30+%2D%64+%61%75%74%6F%5F%70%72%65%70%65%6E%64%5F%66%69%6C%65%3D%70%68%70%3A%2F%2F%69%6E%70%75%74+%2D%6E (198.154.63.131) 11.70ms
WARNING:tornado.access:404 GET /tmUnblock.cgi (149.129.135.107) 6.33ms
WARNING:tornado.access:404 GET /actionnews/index/ (104.202.9.75) 6.78ms
WARNING:tornado.access:404 GET /favicon.ico (192.168.1.35) 6.13ms
  File "/home/pi/M2More/services.py", line 10
    import * from RGB
           ^
SyntaxError: invalid syntax
  File "/home/pi/M2More/services.py", line 10
    import * from RGB
           ^
SyntaxError: invalid syntax
  File "/home/pi/M2More/services.py", line 10
    import * from RGB
           ^
SyntaxError: invalid syntax
  File "/home/pi/M2More/services.py", line 10
    import * from RGB
           ^
SyntaxError: invalid syntax
WARNING:tornado.access:405 CONNECT mx2.mail2000.com.tw:25 (1.161.30.148) 6.86ms
WARNING:tornado.access:404 GET /fkfk/fkf/fk.php (176.44.33.6) 6.91ms
WARNING:tornado.access:404 GET /phpMyAdmin/scripts/setup.php (176.44.33.6) 6.82ms
WARNING:tornado.access:404 GET /pma/scripts/setup.php (176.44.33.6) 6.93ms
WARNING:tornado.access:404 GET /myadmin/scripts/setup.php (176.44.33.6) 6.80ms
WARNING:tornado.access:404 GET /favicon.ico (212.55.21.48) 6.09ms
WARNING:tornado.access:404 GET /favicon.ico (212.55.21.48) 6.27ms
ERROR:tornado.application:Uncaught exception GET /statistics (212.55.21.48)
HTTPServerRequest(protocol='http', host='rpibio.noip.me', method='GET', uri='/statistics', version='HTTP/1.1', remote_ip='212.55.21.48', headers={'Connection': 'keep-alive', 'Accept-Language': 'en-US,en;q=0.8,es;q=0.6', 'Accept-Encoding': 'gzip, deflate, sdch', 'Host': 'rpibio.noip.me', 'Accept': 'text/html,application/xhtml+xml,application/xml;q=0.9,image/webp,*/*;q=0.8', 'User-Agent': 'Mozilla/5.0 (Windows NT 6.1) AppleWebKit/537.36 (KHTML, like Gecko) Chrome/39.0.2171.95 Safari/537.36'})
Traceback (most recent call last):
  File "/usr/local/lib/python2.7/dist-packages/tornado/web.py", line 1332, in _execute
    result = method(*self.path_args, **self.path_kwargs)
  File "/home/pi/M2More/services.py", line 33, in get
    with con:
NameError: global name 'con' is not defined
ERROR:tornado.access:500 GET /statistics (212.55.21.48) 241.84ms
ERROR:tornado.application:Uncaught exception GET /statistics (212.55.21.48)
HTTPServerRequest(protocol='http', host='rpibio.noip.me', method='GET', uri='/statistics', version='HTTP/1.1', remote_ip='212.55.21.48', headers={'Connection': 'keep-alive', 'Accept-Language': 'en-US,en;q=0.8,es;q=0.6', 'Accept-Encoding': 'gzip, deflate, sdch', 'Cache-Control': 'max-age=0', 'Host': 'rpibio.noip.me', 'Accept': 'text/html,application/xhtml+xml,application/xml;q=0.9,image/webp,*/*;q=0.8', 'User-Agent': 'Mozilla/5.0 (Windows NT 6.1) AppleWebKit/537.36 (KHTML, like Gecko) Chrome/39.0.2171.95 Safari/537.36'})
Traceback (most recent call last):
  File "/usr/local/lib/python2.7/dist-packages/tornado/web.py", line 1332, in _execute
    result = method(*self.path_args, **self.path_kwargs)
  File "/home/pi/M2More/services.py", line 33, in get
    con = database_connect(connection)
NameError: global name 'connection' is not defined
ERROR:tornado.access:500 GET /statistics (212.55.21.48) 26.60ms
ERROR:tornado.application:Uncaught exception GET /statistics (212.55.21.48)
HTTPServerRequest(protocol='http', host='rpibio.noip.me', method='GET', uri='/statistics', version='HTTP/1.1', remote_ip='212.55.21.48', headers={'Connection': 'keep-alive', 'Accept-Language': 'en-US,en;q=0.8,es;q=0.6', 'Accept-Encoding': 'gzip, deflate, sdch', 'Cache-Control': 'max-age=0', 'Host': 'rpibio.noip.me', 'Accept': 'text/html,application/xhtml+xml,application/xml;q=0.9,image/webp,*/*;q=0.8', 'User-Agent': 'Mozilla/5.0 (Windows NT 6.1) AppleWebKit/537.36 (KHTML, like Gecko) Chrome/39.0.2171.95 Safari/537.36'})
Traceback (most recent call last):
  File "/usr/local/lib/python2.7/dist-packages/tornado/web.py", line 1332, in _execute
    result = method(*self.path_args, **self.path_kwargs)
  File "/home/pi/M2More/services.py", line 33, in get
    con = database_connect(connection)
NameError: global name 'connection' is not defined
ERROR:tornado.access:500 GET /statistics (212.55.21.48) 12.04ms
ERROR:tornado.application:Uncaught exception GET /statistics (212.55.21.48)
HTTPServerRequest(protocol='http', host='rpibio.noip.me', method='GET', uri='/statistics', version='HTTP/1.1', remote_ip='212.55.21.48', headers={'Connection': 'keep-alive', 'Accept-Language': 'en-US,en;q=0.8,es;q=0.6', 'Accept-Encoding': 'gzip, deflate, sdch', 'Cache-Control': 'max-age=0', 'Host': 'rpibio.noip.me', 'Accept': 'text/html,application/xhtml+xml,application/xml;q=0.9,image/webp,*/*;q=0.8', 'User-Agent': 'Mozilla/5.0 (Windows NT 6.1) AppleWebKit/537.36 (KHTML, like Gecko) Chrome/39.0.2171.95 Safari/537.36'})
Traceback (most recent call last):
  File "/usr/local/lib/python2.7/dist-packages/tornado/web.py", line 1332, in _execute
    result = method(*self.path_args, **self.path_kwargs)
  File "/home/pi/M2More/services.py", line 33, in get
    con = database_connect(connection)
NameError: global name 'connection' is not defined
ERROR:tornado.access:500 GET /statistics (212.55.21.48) 11.99ms
Traceback (most recent call last):
  File "/home/pi/M2More/services.py", line 73, in <module>
    RGB.activate(RGB_BLUE)
NameError: name 'RGB_BLUE' is not defined
Traceback (most recent call last):
  File "/home/pi/M2More/services.py", line 73, in <module>
    RGB.activate(RGB_BLUE)
NameError: name 'RGB_BLUE' is not defined
Traceback (most recent call last):
  File "/home/pi/M2More/services.py", line 73, in <module>
    RGB.activate(RGB_BLUE)
NameError: name 'RGB_BLUE' is not defined
Traceback (most recent call last):
  File "/home/pi/M2More/services.py", line 73, in <module>
    RGB.activate(RGB_BLUE)
NameError: name 'RGB_BLUE' is not defined
Traceback (most recent call last):
  File "/home/pi/M2More/services.py", line 73, in <module>
    RGB.activate(RGB_BLUE)
NameError: name 'RGB_BLUE' is not defined
Traceback (most recent call last):
  File "/home/pi/M2More/services.py", line 73, in <module>
    RGB.activate(RGB_BLUE)
NameError: name 'RGB_BLUE' is not defined
Traceback (most recent call last):
  File "/home/pi/M2More/services.py", line 73, in <module>
    RGB.activate(RGB_BLUE)
NameError: name 'RGB_BLUE' is not defined
Traceback (most recent call last):
  File "/home/pi/M2More/services.py", line 73, in <module>
    RGB.activate(RGB_BLUE)
NameError: name 'RGB_BLUE' is not defined
Traceback (most recent call last):
  File "/home/pi/M2More/services.py", line 73, in <module>
    RGB.activate(RGB_BLUE)
NameError: name 'RGB_BLUE' is not defined
Traceback (most recent call last):
  File "/home/pi/M2More/services.py", line 73, in <module>
    RGB.activate(RGB_BLUE)
NameError: name 'RGB_BLUE' is not defined
Traceback (most recent call last):
  File "/home/pi/M2More/services.py", line 73, in <module>
    RGB.activate(RGB_BLUE)
NameError: name 'RGB_BLUE' is not defined
Traceback (most recent call last):
  File "/home/pi/M2More/services.py", line 73, in <module>
    RGB.activate(RGB_BLUE)
NameError: name 'RGB_BLUE' is not defined
Traceback (most recent call last):
  File "/home/pi/M2More/services.py", line 73, in <module>
    RGB.activate(RGB_BLUE)
NameError: name 'RGB_BLUE' is not defined
Traceback (most recent call last):
  File "/home/pi/M2More/services.py", line 73, in <module>
    RGB.activate(RGB_BLUE)
NameError: name 'RGB_BLUE' is not defined
Traceback (most recent call last):
  File "/home/pi/M2More/services.py", line 73, in <module>
    RGB.activate(RGB_BLUE)
NameError: name 'RGB_BLUE' is not defined
Traceback (most recent call last):
  File "/home/pi/M2More/services.py", line 73, in <module>
    RGB.activate(RGB_BLUE)
NameError: name 'RGB_BLUE' is not defined
Traceback (most recent call last):
  File "/home/pi/M2More/services.py", line 73, in <module>
    RGB.activate(RGB_BLUE)
NameError: name 'RGB_BLUE' is not defined
Traceback (most recent call last):
  File "/home/pi/M2More/services.py", line 73, in <module>
    RGB.activate(RGB_BLUE)
NameError: name 'RGB_BLUE' is not defined
Traceback (most recent call last):
  File "/home/pi/M2More/services.py", line 73, in <module>
    RGB.activate(RGB_BLUE)
NameError: name 'RGB_BLUE' is not defined
Traceback (most recent call last):
  File "/home/pi/M2More/services.py", line 73, in <module>
    RGB.activate(RGB_BLUE)
NameError: name 'RGB_BLUE' is not defined
Traceback (most recent call last):
  File "/home/pi/M2More/services.py", line 73, in <module>
    RGB.activate(RGB_BLUE)
NameError: name 'RGB_BLUE' is not defined
Traceback (most recent call last):
  File "/home/pi/M2More/services.py", line 73, in <module>
    RGB.activate(RGB_BLUE)
NameError: name 'RGB_BLUE' is not defined
Traceback (most recent call last):
  File "/home/pi/M2More/services.py", line 73, in <module>
    RGB.activate(RGB_BLUE)
NameError: name 'RGB_BLUE' is not defined
Traceback (most recent call last):
  File "/home/pi/M2More/services.py", line 73, in <module>
    RGB.activate(RGB_BLUE)
NameError: name 'RGB_BLUE' is not defined
Traceback (most recent call last):
  File "/home/pi/M2More/services.py", line 73, in <module>
    RGB.activate(RGB_BLUE)
NameError: name 'RGB_BLUE' is not defined
Traceback (most recent call last):
  File "/home/pi/M2More/services.py", line 73, in <module>
    RGB.activate(RGB_BLUE)
NameError: name 'RGB_BLUE' is not defined
Traceback (most recent call last):
  File "/home/pi/M2More/services.py", line 73, in <module>
    RGB.activate(RGB_BLUE)
NameError: name 'RGB_BLUE' is not defined
Traceback (most recent call last):
  File "/home/pi/M2More/services.py", line 73, in <module>
    RGB.activate(RGB_BLUE)
NameError: name 'RGB_BLUE' is not defined
Traceback (most recent call last):
  File "/home/pi/M2More/services.py", line 73, in <module>
    RGB.activate(RGB_BLUE)
NameError: name 'RGB_BLUE' is not defined
Traceback (most recent call last):
  File "/home/pi/M2More/services.py", line 73, in <module>
    RGB.activate(RGB_BLUE)
NameError: name 'RGB_BLUE' is not defined
Traceback (most recent call last):
  File "/home/pi/M2More/services.py", line 73, in <module>
    RGB.activate(RGB_BLUE)
NameError: name 'RGB_BLUE' is not defined
Traceback (most recent call last):
  File "/home/pi/M2More/services.py", line 73, in <module>
    RGB.activate(RGB_BLUE)
NameError: name 'RGB_BLUE' is not defined
Traceback (most recent call last):
  File "/home/pi/M2More/services.py", line 74, in <module>
    sleep(1)
NameError: name 'sleep' is not defined
Traceback (most recent call last):
  File "/home/pi/M2More/services.py", line 74, in <module>
    sleep(1)
NameError: name 'sleep' is not defined
Traceback (most recent call last):
  File "/home/pi/M2More/services.py", line 74, in <module>
    sleep(1)
NameError: name 'sleep' is not defined
Traceback (most recent call last):
  File "/home/pi/M2More/services.py", line 74, in <module>
    sleep(1)
NameError: name 'sleep' is not defined
Traceback (most recent call last):
  File "/home/pi/M2More/services.py", line 74, in <module>
    sleep(1)
NameError: name 'sleep' is not defined
Traceback (most recent call last):
  File "/home/pi/M2More/services.py", line 74, in <module>
    sleep(1)
NameError: name 'sleep' is not defined
Traceback (most recent call last):
  File "/home/pi/M2More/services.py", line 74, in <module>
    sleep(1)
NameError: name 'sleep' is not defined
Traceback (most recent call last):
  File "/home/pi/M2More/services.py", line 74, in <module>
    sleep(1)
NameError: name 'sleep' is not defined
Traceback (most recent call last):
  File "/home/pi/M2More/services.py", line 74, in <module>
    sleep(1)
NameError: name 'sleep' is not defined
Traceback (most recent call last):
  File "/home/pi/M2More/services.py", line 74, in <module>
    sleep(1)
NameError: name 'sleep' is not defined
Traceback (most recent call last):
  File "/home/pi/M2More/services.py", line 74, in <module>
    sleep(1)
NameError: name 'sleep' is not defined
Traceback (most recent call last):
  File "/home/pi/M2More/services.py", line 74, in <module>
    sleep(1)
NameError: name 'sleep' is not defined
Traceback (most recent call last):
  File "/home/pi/M2More/services.py", line 74, in <module>
    sleep(1)
NameError: name 'sleep' is not defined
Traceback (most recent call last):
  File "/home/pi/M2More/services.py", line 74, in <module>
    sleep(1)
NameError: name 'sleep' is not defined
Traceback (most recent call last):
  File "/home/pi/M2More/services.py", line 74, in <module>
    sleep(1)
NameError: name 'sleep' is not defined
Traceback (most recent call last):
  File "/home/pi/M2More/services.py", line 74, in <module>
    sleep(1)
NameError: name 'sleep' is not defined
Traceback (most recent call last):
  File "/home/pi/M2More/services.py", line 74, in <module>
    sleep(1)
NameError: name 'sleep' is not defined
Traceback (most recent call last):
  File "/home/pi/M2More/services.py", line 74, in <module>
    sleep(1)
NameError: name 'sleep' is not defined
Traceback (most recent call last):
  File "/home/pi/M2More/services.py", line 74, in <module>
    sleep(1)
NameError: name 'sleep' is not defined
Traceback (most recent call last):
  File "/home/pi/M2More/services.py", line 74, in <module>
    sleep(1)
NameError: name 'sleep' is not defined
Traceback (most recent call last):
  File "/home/pi/M2More/services.py", line 74, in <module>
    sleep(1)
NameError: name 'sleep' is not defined
Traceback (most recent call last):
  File "/home/pi/M2More/services.py", line 74, in <module>
    sleep(1)
NameError: name 'sleep' is not defined
Traceback (most recent call last):
  File "/home/pi/M2More/services.py", line 74, in <module>
    sleep(1)
NameError: name 'sleep' is not defined
Traceback (most recent call last):
  File "/home/pi/M2More/services.py", line 74, in <module>
    sleep(1)
NameError: name 'sleep' is not defined
Traceback (most recent call last):
  File "/home/pi/M2More/services.py", line 74, in <module>
    sleep(1)
NameError: name 'sleep' is not defined
Traceback (most recent call last):
  File "/home/pi/M2More/services.py", line 74, in <module>
    sleep(1)
NameError: name 'sleep' is not defined
Traceback (most recent call last):
  File "/home/pi/M2More/services.py", line 74, in <module>
    sleep(1)
NameError: name 'sleep' is not defined
Traceback (most recent call last):
  File "/home/pi/M2More/services.py", line 74, in <module>
    sleep(1)
NameError: name 'sleep' is not defined
Traceback (most recent call last):
  File "/home/pi/M2More/services.py", line 74, in <module>
    sleep(1)
NameError: name 'sleep' is not defined
Traceback (most recent call last):
  File "/home/pi/M2More/services.py", line 74, in <module>
    sleep(1)
NameError: name 'sleep' is not defined
Traceback (most recent call last):
  File "/home/pi/M2More/services.py", line 74, in <module>
    sleep(1)
NameError: name 'sleep' is not defined
Traceback (most recent call last):
  File "/home/pi/M2More/services.py", line 74, in <module>
    sleep(1)
NameError: name 'sleep' is not defined
Traceback (most recent call last):
  File "/home/pi/M2More/services.py", line 74, in <module>
    RGB.activate(RGB.RGB_BLUE)
NameError: name 'sleep' is not defined
WARNING:tornado.access:404 GET /favicon.ico (66.249.81.169) 6.46ms
Traceback (most recent call last):
  File "/home/pi/M2More/services.py", line 48, in <module>
    class DataHandler(tornado.we.RequestHandler):
AttributeError: 'module' object has no attribute 'we'
Traceback (most recent call last):
  File "/home/pi/M2More/services.py", line 48, in <module>
    class DataHandler(tornado.we.RequestHandler):
AttributeError: 'module' object has no attribute 'we'
Traceback (most recent call last):
  File "/home/pi/M2More/services.py", line 48, in <module>
    class DataHandler(tornado.we.RequestHandler):
AttributeError: 'module' object has no attribute 'we'
Traceback (most recent call last):
  File "/home/pi/M2More/services.py", line 48, in <module>
    class DataHandler(tornado.we.RequestHandler):
AttributeError: 'module' object has no attribute 'we'
Traceback (most recent call last):
  File "/home/pi/M2More/services.py", line 48, in <module>
    class DataHandler(tornado.we.RequestHandler):
AttributeError: 'module' object has no attribute 'we'
Traceback (most recent call last):
  File "/home/pi/M2More/services.py", line 48, in <module>
    class DataHandler(tornado.we.RequestHandler):
AttributeError: 'module' object has no attribute 'we'
Traceback (most recent call last):
  File "/home/pi/M2More/services.py", line 48, in <module>
    class DataHandler(tornado.we.RequestHandler):
AttributeError: 'module' object has no attribute 'we'
Traceback (most recent call last):
  File "/home/pi/M2More/services.py", line 48, in <module>
    class DataHandler(tornado.we.RequestHandler):
AttributeError: 'module' object has no attribute 'we'
Traceback (most recent call last):
  File "/home/pi/M2More/services.py", line 48, in <module>
    class DataHandler(tornado.we.RequestHandler):
AttributeError: 'module' object has no attribute 'we'
Traceback (most recent call last):
  File "/home/pi/M2More/services.py", line 48, in <module>
    class DataHandler(tornado.we.RequestHandler):
AttributeError: 'module' object has no attribute 'we'
Traceback (most recent call last):
  File "/home/pi/M2More/services.py", line 48, in <module>
    class DataHandler(tornado.we.RequestHandler):
AttributeError: 'module' object has no attribute 'we'
Traceback (most recent call last):
  File "/home/pi/M2More/services.py", line 48, in <module>
    class DataHandler(tornado.we.RequestHandler):
AttributeError: 'module' object has no attribute 'we'
Traceback (most recent call last):
  File "/home/pi/M2More/services.py", line 48, in <module>
    class DataHandler(tornado.we.RequestHandler):
AttributeError: 'module' object has no attribute 'we'
Traceback (most recent call last):
  File "/home/pi/M2More/services.py", line 48, in <module>
    class DataHandler(tornado.we.RequestHandler):
AttributeError: 'module' object has no attribute 'we'
Traceback (most recent call last):
  File "/home/pi/M2More/services.py", line 48, in <module>
    class DataHandler(tornado.we.RequestHandler):
AttributeError: 'module' object has no attribute 'we'
Traceback (most recent call last):
  File "/home/pi/M2More/services.py", line 48, in <module>
    class DataHandler(tornado.we.RequestHandler):
AttributeError: 'module' object has no attribute 'we'
ERROR:tornado.application:Uncaught exception GET /data (212.55.21.48)
HTTPServerRequest(protocol='http', host='rpibio.noip.me', method='GET', uri='/data', version='HTTP/1.1', remote_ip='212.55.21.48', headers={'Accept-Language': 'en-US,en;q=0.8,es;q=0.6', 'Accept-Encoding': 'gzip, deflate, sdch', 'Host': 'rpibio.noip.me', 'Accept': 'text/html,application/xhtml+xml,application/xml;q=0.9,image/webp,*/*;q=0.8', 'User-Agent': 'Mozilla/5.0 (Windows NT 6.1) AppleWebKit/537.36 (KHTML, like Gecko) Chrome/39.0.2171.95 Safari/537.36', 'Connection': 'keep-alive', 'Cache-Control': 'max-age=0', 'If-None-Match': '"df28c41485a3ec8e5ec4f847e5e9634059b7774a"'})
Traceback (most recent call last):
  File "/usr/local/lib/python2.7/dist-packages/tornado/web.py", line 1332, in _execute
    result = method(*self.path_args, **self.path_kwargs)
  File "/home/pi/M2More/services.py", line 51, in get
    with row:
NameError: global name 'row' is not defined
ERROR:tornado.access:500 GET /data (212.55.21.48) 205.52ms
ERROR:tornado.application:Uncaught exception GET /data (212.55.21.48)
HTTPServerRequest(protocol='http', host='rpibio.noip.me', method='GET', uri='/data', version='HTTP/1.1', remote_ip='212.55.21.48', headers={'Connection': 'keep-alive', 'Accept-Language': 'en-US,en;q=0.8,es;q=0.6', 'Accept-Encoding': 'gzip, deflate, sdch', 'Host': 'rpibio.noip.me', 'Accept': 'text/html,application/xhtml+xml,application/xml;q=0.9,image/webp,*/*;q=0.8', 'User-Agent': 'Mozilla/5.0 (Windows NT 6.1) AppleWebKit/537.36 (KHTML, like Gecko) Chrome/39.0.2171.95 Safari/537.36'})
Traceback (most recent call last):
  File "/usr/local/lib/python2.7/dist-packages/tornado/web.py", line 1332, in _execute
    result = method(*self.path_args, **self.path_kwargs)
  File "/home/pi/M2More/services.py", line 55, in get
    data_json = json.dumps(data)
  File "/usr/lib/python2.7/json/__init__.py", line 231, in dumps
    return _default_encoder.encode(obj)
  File "/usr/lib/python2.7/json/encoder.py", line 200, in encode
    chunks = self.iterencode(o, _one_shot=True)
  File "/usr/lib/python2.7/json/encoder.py", line 263, in iterencode
    return _iterencode(o, 0)
  File "/usr/lib/python2.7/json/encoder.py", line 177, in default
    raise TypeError(repr(o) + " is not JSON serializable")
TypeError: datetime.datetime(2014, 12, 31, 21, 4) is not JSON serializable
ERROR:tornado.access:500 GET /data (212.55.21.48) 221.02ms
ERROR:tornado.application:Uncaught exception GET /statistics (212.55.21.48)
HTTPServerRequest(protocol='http', host='rpibio.noip.me', method='GET', uri='/statistics', version='HTTP/1.1', remote_ip='212.55.21.48', headers={'Accept-Language': 'en-US,en;q=0.8,es;q=0.6', 'Accept-Encoding': 'gzip, deflate, sdch', 'Host': 'rpibio.noip.me', 'Accept': 'text/html,application/xhtml+xml,application/xml;q=0.9,image/webp,*/*;q=0.8', 'User-Agent': 'Mozilla/5.0 (Windows NT 6.1) AppleWebKit/537.36 (KHTML, like Gecko) Chrome/39.0.2171.95 Safari/537.36', 'Connection': 'keep-alive', 'Cache-Control': 'max-age=0', 'If-None-Match': '"df28c41485a3ec8e5ec4f847e5e9634059b7774a"'})
Traceback (most recent call last):
  File "/usr/local/lib/python2.7/dist-packages/tornado/web.py", line 1332, in _execute
    result = method(*self.path_args, **self.path_kwargs)
  File "/home/pi/M2More/services.py", line 46, in get
    self.write(statistics_json, indent = 2, separators=(',', ': '))
TypeError: write() got an unexpected keyword argument 'indent'
ERROR:tornado.access:500 GET /statistics (212.55.21.48) 211.89ms
ERROR:tornado.application:Uncaught exception GET /statistics (212.55.21.48)
HTTPServerRequest(protocol='http', host='rpibio.noip.me', method='GET', uri='/statistics', version='HTTP/1.1', remote_ip='212.55.21.48', headers={'Connection': 'keep-alive', 'Accept-Language': 'en-US,en;q=0.8,es;q=0.6', 'Accept-Encoding': 'gzip, deflate, sdch', 'Cache-Control': 'max-age=0', 'Host': 'rpibio.noip.me', 'Accept': 'text/html,application/xhtml+xml,application/xml;q=0.9,image/webp,*/*;q=0.8', 'User-Agent': 'Mozilla/5.0 (Windows NT 6.1) AppleWebKit/537.36 (KHTML, like Gecko) Chrome/39.0.2171.95 Safari/537.36'})
Traceback (most recent call last):
  File "/usr/local/lib/python2.7/dist-packages/tornado/web.py", line 1332, in _execute
    result = method(*self.path_args, **self.path_kwargs)
  File "/home/pi/M2More/services.py", line 46, in get
    self.write(statistics_json, indent = 2, separators=(',', ': '))
TypeError: write() got an unexpected keyword argument 'indent'
ERROR:tornado.access:500 GET /statistics (212.55.21.48) 26.29ms
  File "/home/pi/M2More/services.py", line 45
    statistics_json = json.dumps(statistics_dict, indent = 2, separators=(',', ': '), , sort_keys=True) 
                                                                                      ^
SyntaxError: invalid syntax
  File "/home/pi/M2More/services.py", line 45
    statistics_json = json.dumps(statistics_dict, indent = 2, separators=(',', ': '), , sort_keys=True) 
                                                                                      ^
SyntaxError: invalid syntax
  File "/home/pi/M2More/services.py", line 45
    statistics_json = json.dumps(statistics_dict, indent = 2, separators=(',', ': '), , sort_keys=True) 
                                                                                      ^
SyntaxError: invalid syntax
  File "/home/pi/M2More/services.py", line 45
    statistics_json = json.dumps(statistics_dict, indent = 2, separators=(',', ': '), , sort_keys=True) 
                                                                                      ^
SyntaxError: invalid syntax
WARNING:tornado.access:404 GET /favicon.ico (212.55.21.48) 8.86ms
WARNING:tornado.access:404 GET /favicon.ico (212.55.21.48) 6.11ms
ERROR:tornado.application:Uncaught exception GET / (212.55.21.48)
HTTPServerRequest(protocol='http', host='rpibio.noip.me', method='GET', uri='/', version='HTTP/1.1', remote_ip='212.55.21.48', headers={'Accept-Language': 'en-US,en;q=0.8,es;q=0.6', 'Accept-Encoding': 'gzip, deflate, sdch', 'Host': 'rpibio.noip.me', 'Accept': 'text/html,application/xhtml+xml,application/xml;q=0.9,image/webp,*/*;q=0.8', 'User-Agent': 'Mozilla/5.0 (Windows NT 6.1) AppleWebKit/537.36 (KHTML, like Gecko) Chrome/39.0.2171.95 Safari/537.36', 'Connection': 'keep-alive', 'Cache-Control': 'max-age=0', 'If-None-Match': '"03ceb257d34d1cc315460ffd257017eaffdf7f07"'})
Traceback (most recent call last):
  File "/usr/local/lib/python2.7/dist-packages/tornado/web.py", line 1332, in _execute
    result = method(*self.path_args, **self.path_kwargs)
  File "/home/pi/M2More/services.py", line 71, in get
    json = json.dumps(dict, indent = 4, separators=(',', ': '), sort_keys=True)
UnboundLocalError: local variable 'json' referenced before assignment
ERROR:tornado.access:500 GET / (212.55.21.48) 26.76ms
ERROR:tornado.application:Uncaught exception GET /data (212.55.21.48)
HTTPServerRequest(protocol='http', host='rpibio.noip.me', method='GET', uri='/data', version='HTTP/1.1', remote_ip='212.55.21.48', headers={'Connection': 'keep-alive', 'Accept-Language': 'en-US,en;q=0.8,es;q=0.6', 'Accept-Encoding': 'gzip, deflate, sdch', 'If-None-Match': '"c332d39c8dac7946fe97f25319dc1064d1fb0374"', 'Host': 'rpibio.noip.me', 'Accept': 'text/html,application/xhtml+xml,application/xml;q=0.9,image/webp,*/*;q=0.8', 'User-Agent': 'Mozilla/5.0 (Windows NT 6.1) AppleWebKit/537.36 (KHTML, like Gecko) Chrome/39.0.2171.95 Safari/537.36'})
Traceback (most recent call last):
  File "/usr/local/lib/python2.7/dist-packages/tornado/web.py", line 1332, in _execute
    result = method(*self.path_args, **self.path_kwargs)
  File "/home/pi/M2More/services.py", line 65, in get
    self.write(json)
  File "/usr/local/lib/python2.7/dist-packages/tornado/web.py", line 656, in write
    raise TypeError("write() only accepts bytes, unicode, and dict objects")
TypeError: write() only accepts bytes, unicode, and dict objects
ERROR:tornado.access:500 GET /data (212.55.21.48) 224.81ms
ERROR:tornado.application:Uncaught exception GET /data (212.55.21.48)
HTTPServerRequest(protocol='http', host='rpibio.noip.me', method='GET', uri='/data', version='HTTP/1.1', remote_ip='212.55.21.48', headers={'Connection': 'keep-alive', 'Accept-Language': 'en-US,en;q=0.8,es;q=0.6', 'Accept-Encoding': 'gzip, deflate, sdch', 'Cache-Control': 'max-age=0', 'Host': 'rpibio.noip.me', 'Accept': 'text/html,application/xhtml+xml,application/xml;q=0.9,image/webp,*/*;q=0.8', 'User-Agent': 'Mozilla/5.0 (Windows NT 6.1) AppleWebKit/537.36 (KHTML, like Gecko) Chrome/39.0.2171.95 Safari/537.36'})
Traceback (most recent call last):
  File "/usr/local/lib/python2.7/dist-packages/tornado/web.py", line 1332, in _execute
    result = method(*self.path_args, **self.path_kwargs)
  File "/home/pi/M2More/services.py", line 65, in get
    self.write(json)
  File "/usr/local/lib/python2.7/dist-packages/tornado/web.py", line 656, in write
    raise TypeError("write() only accepts bytes, unicode, and dict objects")
TypeError: write() only accepts bytes, unicode, and dict objects
ERROR:tornado.access:500 GET /data (212.55.21.48) 39.01ms
ERROR:tornado.application:Uncaught exception GET /data (212.55.21.48)
HTTPServerRequest(protocol='http', host='rpibio.noip.me', method='GET', uri='/data', version='HTTP/1.1', remote_ip='212.55.21.48', headers={'Connection': 'keep-alive', 'Accept-Language': 'en-US,en;q=0.8,es;q=0.6', 'Accept-Encoding': 'gzip, deflate, sdch', 'Cache-Control': 'max-age=0', 'Host': 'rpibio.noip.me', 'Accept': 'text/html,application/xhtml+xml,application/xml;q=0.9,image/webp,*/*;q=0.8', 'User-Agent': 'Mozilla/5.0 (Windows NT 6.1) AppleWebKit/537.36 (KHTML, like Gecko) Chrome/39.0.2171.95 Safari/537.36'})
Traceback (most recent call last):
  File "/usr/local/lib/python2.7/dist-packages/tornado/web.py", line 1332, in _execute
    result = method(*self.path_args, **self.path_kwargs)
  File "/home/pi/M2More/services.py", line 65, in get
    self.write(json)
  File "/usr/local/lib/python2.7/dist-packages/tornado/web.py", line 656, in write
    raise TypeError("write() only accepts bytes, unicode, and dict objects")
TypeError: write() only accepts bytes, unicode, and dict objects
ERROR:tornado.access:500 GET /data (212.55.21.48) 38.21ms
ERROR:tornado.application:Uncaught exception GET / (212.55.21.48)
HTTPServerRequest(protocol='http', host='rpibio.noip.me', method='GET', uri='/', version='HTTP/1.1', remote_ip='212.55.21.48', headers={'Connection': 'keep-alive', 'Accept-Language': 'en-US,en;q=0.8,es;q=0.6', 'Accept-Encoding': 'gzip, deflate, sdch', 'Cache-Control': 'max-age=0', 'Host': 'rpibio.noip.me', 'Accept': 'text/html,application/xhtml+xml,application/xml;q=0.9,image/webp,*/*;q=0.8', 'User-Agent': 'Mozilla/5.0 (Windows NT 6.1) AppleWebKit/537.36 (KHTML, like Gecko) Chrome/39.0.2171.95 Safari/537.36'})
Traceback (most recent call last):
  File "/usr/local/lib/python2.7/dist-packages/tornado/web.py", line 1332, in _execute
    result = method(*self.path_args, **self.path_kwargs)
  File "/home/pi/M2More/services.py", line 75, in get
    self.write(json_dict)
  File "/usr/local/lib/python2.7/dist-packages/tornado/web.py", line 656, in write
    raise TypeError("write() only accepts bytes, unicode, and dict objects")
TypeError: write() only accepts bytes, unicode, and dict objects
ERROR:tornado.access:500 GET / (212.55.21.48) 30.93ms
ERROR:tornado.application:Uncaught exception GET /statistics (212.55.21.48)
HTTPServerRequest(protocol='http', host='rpibio.noip.me', method='GET', uri='/statistics', version='HTTP/1.1', remote_ip='212.55.21.48', headers={'Connection': 'keep-alive', 'Accept-Language': 'en-US,en;q=0.8,es;q=0.6', 'Accept-Encoding': 'gzip, deflate, sdch', 'If-None-Match': '"3c7e7e820420b49583bdf358fc37898e67fddb82"', 'Host': 'rpibio.noip.me', 'Accept': 'text/html,application/xhtml+xml,application/xml;q=0.9,image/webp,*/*;q=0.8', 'User-Agent': 'Mozilla/5.0 (Windows NT 6.1) AppleWebKit/537.36 (KHTML, like Gecko) Chrome/39.0.2171.95 Safari/537.36'})
Traceback (most recent call last):
  File "/usr/local/lib/python2.7/dist-packages/tornado/web.py", line 1332, in _execute
    result = method(*self.path_args, **self.path_kwargs)
  File "/home/pi/M2More/services.py", line 55, in get
    self.write(json_dict)
  File "/usr/local/lib/python2.7/dist-packages/tornado/web.py", line 656, in write
    raise TypeError("write() only accepts bytes, unicode, and dict objects")
TypeError: write() only accepts bytes, unicode, and dict objects
ERROR:tornado.access:500 GET /statistics (212.55.21.48) 197.81ms
WARNING:tornado.access:404 GET /favicon.ico (88.28.27.108) 6.52ms
  File "/home/pi/M2More/services.py", line 44
    with con:    
    ^
IndentationError: unexpected indent
  File "/home/pi/M2More/services.py", line 44
    with con:    
    ^
IndentationError: unexpected indent
  File "/home/pi/M2More/services.py", line 44
    with con:    
    ^
IndentationError: unexpected indent
  File "/home/pi/M2More/services.py", line 44
    with con:    
    ^
IndentationError: unexpected indent
  File "/home/pi/M2More/services.py", line 47
    with con:    
    ^
IndentationError: unexpected indent
  File "/home/pi/M2More/services.py", line 47
    with con:    
    ^
IndentationError: unexpected indent
  File "/home/pi/M2More/services.py", line 47
    with con:    
    ^
IndentationError: unexpected indent
  File "/home/pi/M2More/services.py", line 47
    with con:    
    ^
IndentationError: unexpected indent
  File "/home/pi/M2More/services.py", line 84
    dict = []
    ^
IndentationError: unexpected indent
  File "/home/pi/M2More/services.py", line 84
    dict = []
    ^
IndentationError: unexpected indent
  File "/home/pi/M2More/services.py", line 84
    dict = []
    ^
IndentationError: unexpected indent
  File "/home/pi/M2More/services.py", line 84
    dict = []
    ^
IndentationError: unexpected indent
ERROR:tornado.application:Uncaught exception GET /data (88.31.193.13)
HTTPServerRequest(protocol='http', host='rpibio.noip.me', method='GET', uri='/data', version='HTTP/1.1', remote_ip='88.31.193.13', headers={'Accept-Language': 'en-US,en;q=0.8,es;q=0.6', 'Accept-Encoding': 'gzip, deflate, sdch', 'Host': 'rpibio.noip.me', 'Accept': 'text/html,application/xhtml+xml,application/xml;q=0.9,image/webp,*/*;q=0.8', 'User-Agent': 'Mozilla/5.0 (Windows NT 6.1) AppleWebKit/537.36 (KHTML, like Gecko) Chrome/39.0.2171.95 Safari/537.36', 'Connection': 'keep-alive', 'Cache-Control': 'max-age=43200', 'If-None-Match': '"fbb7ab97a8ed0aa23fe1a9ff0d26b669f95b1584"'})
Traceback (most recent call last):
  File "/usr/local/lib/python2.7/dist-packages/tornado/web.py", line 1332, in _execute
    result = method(*self.path_args, **self.path_kwargs)
  File "/home/pi/M2More/services.py", line 85, in get
    for row in rows:
NameError: global name 'rows' is not defined
ERROR:tornado.access:500 GET /data (88.31.193.13) 204.78ms
ERROR:tornado.application:Uncaught exception GET /statistics (88.31.193.13)
HTTPServerRequest(protocol='http', host='rpibio.noip.me', method='GET', uri='/statistics', version='HTTP/1.1', remote_ip='88.31.193.13', headers={'Accept-Language': 'en-US,en;q=0.8,es;q=0.6', 'Accept-Encoding': 'gzip, deflate, sdch', 'Host': 'rpibio.noip.me', 'Accept': 'text/html,application/xhtml+xml,application/xml;q=0.9,image/webp,*/*;q=0.8', 'User-Agent': 'Mozilla/5.0 (Windows NT 6.1) AppleWebKit/537.36 (KHTML, like Gecko) Chrome/39.0.2171.95 Safari/537.36', 'Connection': 'keep-alive', 'Cache-Control': 'max-age=43200', 'If-None-Match': '"408d35291daad788e50eb54b45087f28d6339606"'})
Traceback (most recent call last):
  File "/usr/local/lib/python2.7/dist-packages/tornado/web.py", line 1332, in _execute
    result = method(*self.path_args, **self.path_kwargs)
  File "/home/pi/M2More/services.py", line 60, in get
    "SELECT COUNT(*) FROM log WHERE data = 1"], ["ONE", "ONE", "ONE"])
ValueError: need more than 1 value to unpack
ERROR:tornado.access:500 GET /statistics (88.31.193.13) 32.86ms
ERROR:tornado.application:Uncaught exception GET /data (88.31.193.13)
HTTPServerRequest(protocol='http', host='rpibio.noip.me', method='GET', uri='/data', version='HTTP/1.1', remote_ip='88.31.193.13', headers={'Accept-Language': 'en-US,en;q=0.8,es;q=0.6', 'Accept-Encoding': 'gzip, deflate, sdch', 'Host': 'rpibio.noip.me', 'Accept': 'text/html,application/xhtml+xml,application/xml;q=0.9,image/webp,*/*;q=0.8', 'User-Agent': 'Mozilla/5.0 (Windows NT 6.1) AppleWebKit/537.36 (KHTML, like Gecko) Chrome/39.0.2171.95 Safari/537.36', 'Connection': 'keep-alive', 'Cache-Control': 'max-age=43200', 'If-None-Match': '"587e34178722c75d2bf16072aff7721d500e06ac"'})
Traceback (most recent call last):
  File "/usr/local/lib/python2.7/dist-packages/tornado/web.py", line 1332, in _execute
    result = method(*self.path_args, **self.path_kwargs)
  File "/home/pi/M2More/services.py", line 82, in get
    for row in rows[0]:
NameError: global name 'rows' is not defined
ERROR:tornado.access:500 GET /data (88.31.193.13) 36.61ms
WARNING:tornado.access:404 GET http://s1.bdstatic.com/r/www/cache/static/home/img/logos/nuomi_ade5465d.png (125.64.35.68) 6.23ms
WARNING:tornado.access:404 GET http://s1.bdstatic.com/r/www/cache/static/home/img/logos/nuomi_ade5465d.png (125.64.35.67) 6.40ms
WARNING:tornado.access:404 GET http://1111.ip138.com/ic.asp (222.186.21.98) 6.37ms
WARNING:tornado.access:404 GET /favicon.ico (192.168.1.38) 6.21ms
WARNING:tornado.access:404 GET /favicon.ico (192.168.1.38) 6.34ms
WARNING:tornado.access:404 GET /favicon.ico (66.249.81.163) 7.17ms
WARNING:tornado.access:404 GET /favicon.ico (66.249.81.163) 6.20ms
WARNING:tornado.access:404 GET /favicon.ico (66.249.81.169) 6.39ms
WARNING:tornado.access:404 GET /favicon.ico (192.168.1.35) 6.48ms
  File "/home/pi/M2More/services.py", line 72
    dict.append({ 'records_number': row_list[1][1])
                                                  ^
SyntaxError: invalid syntax
  File "/home/pi/M2More/services.py", line 72
    dict.append({ 'records_number': row_list[1][1])
                                                  ^
SyntaxError: invalid syntax
  File "/home/pi/M2More/services.py", line 72
    dict.append({ 'records_number': row_list[1][1])
                                                  ^
SyntaxError: invalid syntax
  File "/home/pi/M2More/services.py", line 72
    dict.append({ 'records_number': row_list[1][1])
                                                  ^
SyntaxError: invalid syntax
  File "/home/pi/M2More/services.py", line 72
    dict.append({ 'records_number': rows_list[1][1])
                                                   ^
SyntaxError: invalid syntax
  File "/home/pi/M2More/services.py", line 72
    dict.append({ 'records_number': rows_list[1][1])
                                                   ^
SyntaxError: invalid syntax
  File "/home/pi/M2More/services.py", line 72
    dict.append({ 'records_number': rows_list[1][1])
                                                   ^
SyntaxError: invalid syntax
  File "/home/pi/M2More/services.py", line 72
    dict.append({ 'records_number': rows_list[1][1])
                                                   ^
SyntaxError: invalid syntax
ERROR:tornado.application:Uncaught exception GET /data (192.168.1.35)
HTTPServerRequest(protocol='http', host='192.168.1.50', method='GET', uri='/data', version='HTTP/1.1', remote_ip='192.168.1.35', headers={'Accept-Language': 'en-US,en;q=0.8,es;q=0.6', 'Accept-Encoding': 'gzip, deflate, sdch', 'Host': '192.168.1.50', 'Accept': 'text/html,application/xhtml+xml,application/xml;q=0.9,image/webp,*/*;q=0.8', 'User-Agent': 'Mozilla/5.0 (Windows NT 6.1) AppleWebKit/537.36 (KHTML, like Gecko) Chrome/39.0.2171.95 Safari/537.36', 'Connection': 'keep-alive', 'Cookie': '__utma=90629722.1889644263.1420119736.1420119736.1420119736.1; __utmz=90629722.1420119736.1.1.utmcsr=(direct)|utmccn=(direct)|utmcmd=(none)', 'Cache-Control': 'max-age=0', 'If-None-Match': '"708cd6328ca3508e7830ced0bb31b4da71f76b44"'})
Traceback (most recent call last):
  File "/usr/local/lib/python2.7/dist-packages/tornado/web.py", line 1332, in _execute
    result = method(*self.path_args, **self.path_kwargs)
  File "/home/pi/M2More/services.py", line 72, in get
    dict.append({ 'records_number': rows_list[1][1]})
IndexError: tuple index out of range
ERROR:tornado.access:500 GET /data (192.168.1.35) 229.19ms
ERROR:tornado.application:Uncaught exception GET /data (192.168.1.35)
HTTPServerRequest(protocol='http', host='192.168.1.50', method='GET', uri='/data', version='HTTP/1.1', remote_ip='192.168.1.35', headers={'Accept-Language': 'en-US,en;q=0.8,es;q=0.6', 'Accept-Encoding': 'gzip, deflate, sdch', 'Host': '192.168.1.50', 'Accept': 'text/html,application/xhtml+xml,application/xml;q=0.9,image/webp,*/*;q=0.8', 'User-Agent': 'Mozilla/5.0 (Windows NT 6.1) AppleWebKit/537.36 (KHTML, like Gecko) Chrome/39.0.2171.95 Safari/537.36', 'Connection': 'keep-alive', 'Cookie': '__utma=90629722.1889644263.1420119736.1420119736.1420119736.1; __utmz=90629722.1420119736.1.1.utmcsr=(direct)|utmccn=(direct)|utmcmd=(none)', 'Cache-Control': 'max-age=0'})
Traceback (most recent call last):
  File "/usr/local/lib/python2.7/dist-packages/tornado/web.py", line 1332, in _execute
    result = method(*self.path_args, **self.path_kwargs)
  File "/home/pi/M2More/services.py", line 72, in get
    dict.append({ 'records_number': rows_list[1][1]})
IndexError: tuple index out of range
ERROR:tornado.access:500 GET /data (192.168.1.35) 34.97ms
  File "/home/pi/M2More/services.py", line 72
    dict.append('records_number': rows_list[1][0])
                                ^
SyntaxError: invalid syntax
  File "/home/pi/M2More/services.py", line 72
    dict.append('records_number': rows_list[1][0])
                                ^
SyntaxError: invalid syntax
  File "/home/pi/M2More/services.py", line 72
    dict.append('records_number': rows_list[1][0])
                                ^
SyntaxError: invalid syntax
  File "/home/pi/M2More/services.py", line 72
    dict.append('records_number': rows_list[1][0])
                                ^
SyntaxError: invalid syntax
  File "/home/pi/M2More/services.py", line 38
    results_dict = {'results': dict, args, 'datetime': normalized_now}
                                         ^
SyntaxError: invalid syntax
  File "/home/pi/M2More/services.py", line 38
    results_dict = {'results': dict, args, 'datetime': normalized_now}
                                         ^
SyntaxError: invalid syntax
  File "/home/pi/M2More/services.py", line 38
    results_dict = {'results': dict, args, 'datetime': normalized_now}
                                         ^
SyntaxError: invalid syntax
  File "/home/pi/M2More/services.py", line 38
    results_dict = {'results': dict, args, 'datetime': normalized_now}
                                         ^
SyntaxError: invalid syntax
  File "/home/pi/M2More/services.py", line 38
    results_dict = {'results': dict, args, 'datetime': normalized_now}
                                         ^
SyntaxError: invalid syntax
  File "/home/pi/M2More/services.py", line 38
    results_dict = {'results': dict, args, 'datetime': normalized_now}
                                         ^
SyntaxError: invalid syntax
  File "/home/pi/M2More/services.py", line 38
    results_dict = {'results': dict, args, 'datetime': normalized_now}
                                         ^
SyntaxError: invalid syntax
  File "/home/pi/M2More/services.py", line 38
    results_dict = {'results': dict, args, 'datetime': normalized_now}
                                         ^
SyntaxError: invalid syntax
  File "/home/pi/M2More/services.py", line 38
    results_dict = {'results': dict, kwargs, 'datetime': normalized_now}
                                           ^
SyntaxError: invalid syntax
  File "/home/pi/M2More/services.py", line 38
    results_dict = {'results': dict, kwargs, 'datetime': normalized_now}
                                           ^
SyntaxError: invalid syntax
  File "/home/pi/M2More/services.py", line 38
    results_dict = {'results': dict, kwargs, 'datetime': normalized_now}
                                           ^
SyntaxError: invalid syntax
  File "/home/pi/M2More/services.py", line 38
    results_dict = {'results': dict, kwargs, 'datetime': normalized_now}
                                           ^
SyntaxError: invalid syntax
ERROR:tornado.application:Uncaught exception GET /data (192.168.1.35)
HTTPServerRequest(protocol='http', host='192.168.1.50', method='GET', uri='/data', version='HTTP/1.1', remote_ip='192.168.1.35', headers={'Accept-Language': 'en-US,en;q=0.8,es;q=0.6', 'Accept-Encoding': 'gzip, deflate, sdch', 'Host': '192.168.1.50', 'Accept': 'text/html,application/xhtml+xml,application/xml;q=0.9,image/webp,*/*;q=0.8', 'User-Agent': 'Mozilla/5.0 (Windows NT 6.1) AppleWebKit/537.36 (KHTML, like Gecko) Chrome/39.0.2171.95 Safari/537.36', 'Connection': 'keep-alive', 'Cookie': '__utma=90629722.1889644263.1420119736.1420119736.1420119736.1; __utmz=90629722.1420119736.1.1.utmcsr=(direct)|utmccn=(direct)|utmcmd=(none)', 'Cache-Control': 'max-age=0', 'If-None-Match': '"7132d9c28142d71a9db51f516ebcf3ecde6083e6"'})
Traceback (most recent call last):
  File "/usr/local/lib/python2.7/dist-packages/tornado/web.py", line 1332, in _execute
    result = method(*self.path_args, **self.path_kwargs)
  File "/home/pi/M2More/services.py", line 77, in get
    json_dict = dict_to_json(dict, records_number = rows_list[1][0])
  File "/home/pi/M2More/services.py", line 40, in dict_to_json
    results_dict.append(kwargs)
AttributeError: 'dict' object has no attribute 'append'
ERROR:tornado.access:500 GET /data (192.168.1.35) 233.73ms
ERROR:tornado.application:Uncaught exception GET /data (192.168.1.35)
HTTPServerRequest(protocol='http', host='192.168.1.50', method='GET', uri='/data', version='HTTP/1.1', remote_ip='192.168.1.35', headers={'Accept-Language': 'en-US,en;q=0.8,es;q=0.6', 'Accept-Encoding': 'gzip, deflate, sdch', 'Host': '192.168.1.50', 'Accept': 'text/html,application/xhtml+xml,application/xml;q=0.9,image/webp,*/*;q=0.8', 'User-Agent': 'Mozilla/5.0 (Windows NT 6.1) AppleWebKit/537.36 (KHTML, like Gecko) Chrome/39.0.2171.95 Safari/537.36', 'Connection': 'keep-alive', 'Cookie': '__utma=90629722.1889644263.1420119736.1420119736.1420119736.1; __utmz=90629722.1420119736.1.1.utmcsr=(direct)|utmccn=(direct)|utmcmd=(none)', 'Cache-Control': 'max-age=0'})
Traceback (most recent call last):
  File "/usr/local/lib/python2.7/dist-packages/tornado/web.py", line 1332, in _execute
    result = method(*self.path_args, **self.path_kwargs)
  File "/home/pi/M2More/services.py", line 77, in get
    json_dict = dict_to_json(dict, records_number = rows_list[1][0])
  File "/home/pi/M2More/services.py", line 40, in dict_to_json
    results_dict.append(kwargs)
AttributeError: 'dict' object has no attribute 'append'
ERROR:tornado.access:500 GET /data (192.168.1.35) 40.01ms
Traceback (most recent call last):
  File "/home/pi/M2More/services.py", line 90, in <module>
    (r"/data/([^/]+", DataHandler),    
  File "/usr/local/lib/python2.7/dist-packages/tornado/web.py", line 1660, in __init__
    self.add_handlers(".*$", handlers)
  File "/usr/local/lib/python2.7/dist-packages/tornado/web.py", line 1715, in add_handlers
    spec = URLSpec(*spec)
  File "/usr/local/lib/python2.7/dist-packages/tornado/web.py", line 2774, in __init__
    self.regex = re.compile(pattern)
  File "/usr/lib/python2.7/re.py", line 190, in compile
    return _compile(pattern, flags)
  File "/usr/lib/python2.7/re.py", line 242, in _compile
    raise error, v # invalid expression
sre_constants.error: unbalanced parenthesis
Traceback (most recent call last):
  File "/home/pi/M2More/services.py", line 90, in <module>
    (r"/data/([^/]+", DataHandler),    
  File "/usr/local/lib/python2.7/dist-packages/tornado/web.py", line 1660, in __init__
    self.add_handlers(".*$", handlers)
  File "/usr/local/lib/python2.7/dist-packages/tornado/web.py", line 1715, in add_handlers
    spec = URLSpec(*spec)
  File "/usr/local/lib/python2.7/dist-packages/tornado/web.py", line 2774, in __init__
    self.regex = re.compile(pattern)
  File "/usr/lib/python2.7/re.py", line 190, in compile
    return _compile(pattern, flags)
  File "/usr/lib/python2.7/re.py", line 242, in _compile
    raise error, v # invalid expression
sre_constants.error: unbalanced parenthesis
Traceback (most recent call last):
  File "/home/pi/M2More/services.py", line 90, in <module>
    (r"/data/([^/]+", DataHandler),    
  File "/usr/local/lib/python2.7/dist-packages/tornado/web.py", line 1660, in __init__
    self.add_handlers(".*$", handlers)
  File "/usr/local/lib/python2.7/dist-packages/tornado/web.py", line 1715, in add_handlers
    spec = URLSpec(*spec)
  File "/usr/local/lib/python2.7/dist-packages/tornado/web.py", line 2774, in __init__
    self.regex = re.compile(pattern)
  File "/usr/lib/python2.7/re.py", line 190, in compile
    return _compile(pattern, flags)
  File "/usr/lib/python2.7/re.py", line 242, in _compile
    raise error, v # invalid expression
sre_constants.error: unbalanced parenthesis
Traceback (most recent call last):
  File "/home/pi/M2More/services.py", line 90, in <module>
    (r"/data/([^/]+", DataHandler),    
  File "/usr/local/lib/python2.7/dist-packages/tornado/web.py", line 1660, in __init__
    self.add_handlers(".*$", handlers)
  File "/usr/local/lib/python2.7/dist-packages/tornado/web.py", line 1715, in add_handlers
    spec = URLSpec(*spec)
  File "/usr/local/lib/python2.7/dist-packages/tornado/web.py", line 2774, in __init__
    self.regex = re.compile(pattern)
  File "/usr/lib/python2.7/re.py", line 190, in compile
    return _compile(pattern, flags)
  File "/usr/lib/python2.7/re.py", line 242, in _compile
    raise error, v # invalid expression
sre_constants.error: unbalanced parenthesis
Traceback (most recent call last):
  File "/home/pi/M2More/services.py", line 90, in <module>
    (r"/data/([^/]+", DataHandler),    
  File "/usr/local/lib/python2.7/dist-packages/tornado/web.py", line 1660, in __init__
    self.add_handlers(".*$", handlers)
  File "/usr/local/lib/python2.7/dist-packages/tornado/web.py", line 1715, in add_handlers
    spec = URLSpec(*spec)
  File "/usr/local/lib/python2.7/dist-packages/tornado/web.py", line 2774, in __init__
    self.regex = re.compile(pattern)
  File "/usr/lib/python2.7/re.py", line 190, in compile
    return _compile(pattern, flags)
  File "/usr/lib/python2.7/re.py", line 242, in _compile
    raise error, v # invalid expression
sre_constants.error: unbalanced parenthesis
Traceback (most recent call last):
  File "/home/pi/M2More/services.py", line 90, in <module>
    (r"/data/([^/]+", DataHandler),    
  File "/usr/local/lib/python2.7/dist-packages/tornado/web.py", line 1660, in __init__
    self.add_handlers(".*$", handlers)
  File "/usr/local/lib/python2.7/dist-packages/tornado/web.py", line 1715, in add_handlers
    spec = URLSpec(*spec)
  File "/usr/local/lib/python2.7/dist-packages/tornado/web.py", line 2774, in __init__
    self.regex = re.compile(pattern)
  File "/usr/lib/python2.7/re.py", line 190, in compile
    return _compile(pattern, flags)
  File "/usr/lib/python2.7/re.py", line 242, in _compile
    raise error, v # invalid expression
sre_constants.error: unbalanced parenthesis
Traceback (most recent call last):
  File "/home/pi/M2More/services.py", line 90, in <module>
    (r"/data/([^/]+", DataHandler),    
  File "/usr/local/lib/python2.7/dist-packages/tornado/web.py", line 1660, in __init__
    self.add_handlers(".*$", handlers)
  File "/usr/local/lib/python2.7/dist-packages/tornado/web.py", line 1715, in add_handlers
    spec = URLSpec(*spec)
  File "/usr/local/lib/python2.7/dist-packages/tornado/web.py", line 2774, in __init__
    self.regex = re.compile(pattern)
  File "/usr/lib/python2.7/re.py", line 190, in compile
    return _compile(pattern, flags)
  File "/usr/lib/python2.7/re.py", line 242, in _compile
    raise error, v # invalid expression
sre_constants.error: unbalanced parenthesis
Traceback (most recent call last):
  File "/home/pi/M2More/services.py", line 90, in <module>
    (r"/data/([^/]+", DataHandler),    
  File "/usr/local/lib/python2.7/dist-packages/tornado/web.py", line 1660, in __init__
    self.add_handlers(".*$", handlers)
  File "/usr/local/lib/python2.7/dist-packages/tornado/web.py", line 1715, in add_handlers
    spec = URLSpec(*spec)
  File "/usr/local/lib/python2.7/dist-packages/tornado/web.py", line 2774, in __init__
    self.regex = re.compile(pattern)
  File "/usr/lib/python2.7/re.py", line 190, in compile
    return _compile(pattern, flags)
  File "/usr/lib/python2.7/re.py", line 242, in _compile
    raise error, v # invalid expression
sre_constants.error: unbalanced parenthesis
Traceback (most recent call last):
  File "/home/pi/M2More/services.py", line 90, in <module>
    (r"/data/([^/]+", DataHandler),    
  File "/usr/local/lib/python2.7/dist-packages/tornado/web.py", line 1660, in __init__
    self.add_handlers(".*$", handlers)
  File "/usr/local/lib/python2.7/dist-packages/tornado/web.py", line 1715, in add_handlers
    spec = URLSpec(*spec)
  File "/usr/local/lib/python2.7/dist-packages/tornado/web.py", line 2774, in __init__
    self.regex = re.compile(pattern)
  File "/usr/lib/python2.7/re.py", line 190, in compile
    return _compile(pattern, flags)
  File "/usr/lib/python2.7/re.py", line 242, in _compile
    raise error, v # invalid expression
sre_constants.error: unbalanced parenthesis
Traceback (most recent call last):
  File "/home/pi/M2More/services.py", line 90, in <module>
    (r"/data/([^/]+", DataHandler),    
  File "/usr/local/lib/python2.7/dist-packages/tornado/web.py", line 1660, in __init__
    self.add_handlers(".*$", handlers)
  File "/usr/local/lib/python2.7/dist-packages/tornado/web.py", line 1715, in add_handlers
    spec = URLSpec(*spec)
  File "/usr/local/lib/python2.7/dist-packages/tornado/web.py", line 2774, in __init__
    self.regex = re.compile(pattern)
  File "/usr/lib/python2.7/re.py", line 190, in compile
    return _compile(pattern, flags)
  File "/usr/lib/python2.7/re.py", line 242, in _compile
    raise error, v # invalid expression
sre_constants.error: unbalanced parenthesis
Traceback (most recent call last):
  File "/home/pi/M2More/services.py", line 90, in <module>
    (r"/data/([^/]+", DataHandler),    
  File "/usr/local/lib/python2.7/dist-packages/tornado/web.py", line 1660, in __init__
    self.add_handlers(".*$", handlers)
  File "/usr/local/lib/python2.7/dist-packages/tornado/web.py", line 1715, in add_handlers
    spec = URLSpec(*spec)
  File "/usr/local/lib/python2.7/dist-packages/tornado/web.py", line 2774, in __init__
    self.regex = re.compile(pattern)
  File "/usr/lib/python2.7/re.py", line 190, in compile
    return _compile(pattern, flags)
  File "/usr/lib/python2.7/re.py", line 242, in _compile
    raise error, v # invalid expression
sre_constants.error: unbalanced parenthesis
Traceback (most recent call last):
  File "/home/pi/M2More/services.py", line 90, in <module>
    (r"/data/([^/]+", DataHandler),    
  File "/usr/local/lib/python2.7/dist-packages/tornado/web.py", line 1660, in __init__
    self.add_handlers(".*$", handlers)
  File "/usr/local/lib/python2.7/dist-packages/tornado/web.py", line 1715, in add_handlers
    spec = URLSpec(*spec)
  File "/usr/local/lib/python2.7/dist-packages/tornado/web.py", line 2774, in __init__
    self.regex = re.compile(pattern)
  File "/usr/lib/python2.7/re.py", line 190, in compile
    return _compile(pattern, flags)
  File "/usr/lib/python2.7/re.py", line 242, in _compile
    raise error, v # invalid expression
sre_constants.error: unbalanced parenthesis
Traceback (most recent call last):
  File "/home/pi/M2More/services.py", line 90, in <module>
    (r"/data/([^/]+", DataHandler),    
  File "/usr/local/lib/python2.7/dist-packages/tornado/web.py", line 1660, in __init__
    self.add_handlers(".*$", handlers)
  File "/usr/local/lib/python2.7/dist-packages/tornado/web.py", line 1715, in add_handlers
    spec = URLSpec(*spec)
  File "/usr/local/lib/python2.7/dist-packages/tornado/web.py", line 2774, in __init__
    self.regex = re.compile(pattern)
  File "/usr/lib/python2.7/re.py", line 190, in compile
    return _compile(pattern, flags)
  File "/usr/lib/python2.7/re.py", line 242, in _compile
    raise error, v # invalid expression
sre_constants.error: unbalanced parenthesis
Traceback (most recent call last):
  File "/home/pi/M2More/services.py", line 90, in <module>
    (r"/data/([^/]+", DataHandler),    
  File "/usr/local/lib/python2.7/dist-packages/tornado/web.py", line 1660, in __init__
    self.add_handlers(".*$", handlers)
  File "/usr/local/lib/python2.7/dist-packages/tornado/web.py", line 1715, in add_handlers
    spec = URLSpec(*spec)
  File "/usr/local/lib/python2.7/dist-packages/tornado/web.py", line 2774, in __init__
    self.regex = re.compile(pattern)
  File "/usr/lib/python2.7/re.py", line 190, in compile
    return _compile(pattern, flags)
  File "/usr/lib/python2.7/re.py", line 242, in _compile
    raise error, v # invalid expression
sre_constants.error: unbalanced parenthesis
Traceback (most recent call last):
  File "/home/pi/M2More/services.py", line 90, in <module>
    (r"/data/([^/]+", DataHandler),    
  File "/usr/local/lib/python2.7/dist-packages/tornado/web.py", line 1660, in __init__
    self.add_handlers(".*$", handlers)
  File "/usr/local/lib/python2.7/dist-packages/tornado/web.py", line 1715, in add_handlers
    spec = URLSpec(*spec)
  File "/usr/local/lib/python2.7/dist-packages/tornado/web.py", line 2774, in __init__
    self.regex = re.compile(pattern)
  File "/usr/lib/python2.7/re.py", line 190, in compile
    return _compile(pattern, flags)
  File "/usr/lib/python2.7/re.py", line 242, in _compile
    raise error, v # invalid expression
sre_constants.error: unbalanced parenthesis
Traceback (most recent call last):
  File "/home/pi/M2More/services.py", line 90, in <module>
    (r"/data/([^/]+", DataHandler),    
  File "/usr/local/lib/python2.7/dist-packages/tornado/web.py", line 1660, in __init__
    self.add_handlers(".*$", handlers)
  File "/usr/local/lib/python2.7/dist-packages/tornado/web.py", line 1715, in add_handlers
    spec = URLSpec(*spec)
  File "/usr/local/lib/python2.7/dist-packages/tornado/web.py", line 2774, in __init__
    self.regex = re.compile(pattern)
  File "/usr/lib/python2.7/re.py", line 190, in compile
    return _compile(pattern, flags)
  File "/usr/lib/python2.7/re.py", line 242, in _compile
    raise error, v # invalid expression
sre_constants.error: unbalanced parenthesis
Traceback (most recent call last):
  File "/home/pi/M2More/services.py", line 90, in <module>
    (r"/data/([^/]+", DataHandler),    
  File "/usr/local/lib/python2.7/dist-packages/tornado/web.py", line 1660, in __init__
    self.add_handlers(".*$", handlers)
  File "/usr/local/lib/python2.7/dist-packages/tornado/web.py", line 1715, in add_handlers
    spec = URLSpec(*spec)
  File "/usr/local/lib/python2.7/dist-packages/tornado/web.py", line 2774, in __init__
    self.regex = re.compile(pattern)
  File "/usr/lib/python2.7/re.py", line 190, in compile
    return _compile(pattern, flags)
  File "/usr/lib/python2.7/re.py", line 242, in _compile
    raise error, v # invalid expression
sre_constants.error: unbalanced parenthesis
Traceback (most recent call last):
  File "/home/pi/M2More/services.py", line 90, in <module>
    (r"/data/([^/]+", DataHandler),    
  File "/usr/local/lib/python2.7/dist-packages/tornado/web.py", line 1660, in __init__
    self.add_handlers(".*$", handlers)
  File "/usr/local/lib/python2.7/dist-packages/tornado/web.py", line 1715, in add_handlers
    spec = URLSpec(*spec)
  File "/usr/local/lib/python2.7/dist-packages/tornado/web.py", line 2774, in __init__
    self.regex = re.compile(pattern)
  File "/usr/lib/python2.7/re.py", line 190, in compile
    return _compile(pattern, flags)
  File "/usr/lib/python2.7/re.py", line 242, in _compile
    raise error, v # invalid expression
sre_constants.error: unbalanced parenthesis
Traceback (most recent call last):
  File "/home/pi/M2More/services.py", line 90, in <module>
    (r"/data/([^/]+", DataHandler),    
  File "/usr/local/lib/python2.7/dist-packages/tornado/web.py", line 1660, in __init__
    self.add_handlers(".*$", handlers)
  File "/usr/local/lib/python2.7/dist-packages/tornado/web.py", line 1715, in add_handlers
    spec = URLSpec(*spec)
  File "/usr/local/lib/python2.7/dist-packages/tornado/web.py", line 2774, in __init__
    self.regex = re.compile(pattern)
  File "/usr/lib/python2.7/re.py", line 190, in compile
    return _compile(pattern, flags)
  File "/usr/lib/python2.7/re.py", line 242, in _compile
    raise error, v # invalid expression
sre_constants.error: unbalanced parenthesis
Traceback (most recent call last):
  File "/home/pi/M2More/services.py", line 90, in <module>
    (r"/data/([^/]+", DataHandler),    
  File "/usr/local/lib/python2.7/dist-packages/tornado/web.py", line 1660, in __init__
    self.add_handlers(".*$", handlers)
  File "/usr/local/lib/python2.7/dist-packages/tornado/web.py", line 1715, in add_handlers
    spec = URLSpec(*spec)
  File "/usr/local/lib/python2.7/dist-packages/tornado/web.py", line 2774, in __init__
    self.regex = re.compile(pattern)
  File "/usr/lib/python2.7/re.py", line 190, in compile
    return _compile(pattern, flags)
  File "/usr/lib/python2.7/re.py", line 242, in _compile
    raise error, v # invalid expression
sre_constants.error: unbalanced parenthesis
Traceback (most recent call last):
  File "/home/pi/M2More/services.py", line 90, in <module>
    (r"/data/([^/]+", DataHandler),    
  File "/usr/local/lib/python2.7/dist-packages/tornado/web.py", line 1660, in __init__
    self.add_handlers(".*$", handlers)
  File "/usr/local/lib/python2.7/dist-packages/tornado/web.py", line 1715, in add_handlers
    spec = URLSpec(*spec)
  File "/usr/local/lib/python2.7/dist-packages/tornado/web.py", line 2774, in __init__
    self.regex = re.compile(pattern)
  File "/usr/lib/python2.7/re.py", line 190, in compile
    return _compile(pattern, flags)
  File "/usr/lib/python2.7/re.py", line 242, in _compile
    raise error, v # invalid expression
sre_constants.error: unbalanced parenthesis
Traceback (most recent call last):
  File "/home/pi/M2More/services.py", line 90, in <module>
    (r"/data/([^/]+", DataHandler),    
  File "/usr/local/lib/python2.7/dist-packages/tornado/web.py", line 1660, in __init__
    self.add_handlers(".*$", handlers)
  File "/usr/local/lib/python2.7/dist-packages/tornado/web.py", line 1715, in add_handlers
    spec = URLSpec(*spec)
  File "/usr/local/lib/python2.7/dist-packages/tornado/web.py", line 2774, in __init__
    self.regex = re.compile(pattern)
  File "/usr/lib/python2.7/re.py", line 190, in compile
    return _compile(pattern, flags)
  File "/usr/lib/python2.7/re.py", line 242, in _compile
    raise error, v # invalid expression
sre_constants.error: unbalanced parenthesis
Traceback (most recent call last):
  File "/home/pi/M2More/services.py", line 90, in <module>
    (r"/data/([^/]+", DataHandler),    
  File "/usr/local/lib/python2.7/dist-packages/tornado/web.py", line 1660, in __init__
    self.add_handlers(".*$", handlers)
  File "/usr/local/lib/python2.7/dist-packages/tornado/web.py", line 1715, in add_handlers
    spec = URLSpec(*spec)
  File "/usr/local/lib/python2.7/dist-packages/tornado/web.py", line 2774, in __init__
    self.regex = re.compile(pattern)
  File "/usr/lib/python2.7/re.py", line 190, in compile
    return _compile(pattern, flags)
  File "/usr/lib/python2.7/re.py", line 242, in _compile
    raise error, v # invalid expression
sre_constants.error: unbalanced parenthesis
Traceback (most recent call last):
  File "/home/pi/M2More/services.py", line 90, in <module>
    (r"/data/([^/]+", DataHandler),    
  File "/usr/local/lib/python2.7/dist-packages/tornado/web.py", line 1660, in __init__
    self.add_handlers(".*$", handlers)
  File "/usr/local/lib/python2.7/dist-packages/tornado/web.py", line 1715, in add_handlers
    spec = URLSpec(*spec)
  File "/usr/local/lib/python2.7/dist-packages/tornado/web.py", line 2774, in __init__
    self.regex = re.compile(pattern)
  File "/usr/lib/python2.7/re.py", line 190, in compile
    return _compile(pattern, flags)
  File "/usr/lib/python2.7/re.py", line 242, in _compile
    raise error, v # invalid expression
sre_constants.error: unbalanced parenthesis
Traceback (most recent call last):
  File "/home/pi/M2More/services.py", line 90, in <module>
    (r"/data/([^/]+)", DataHandler),    
  File "/usr/local/lib/python2.7/dist-packages/tornado/web.py", line 1660, in __init__
    self.add_handlers(".*$", handlers)
  File "/usr/local/lib/python2.7/dist-packages/tornado/web.py", line 1715, in add_handlers
    spec = URLSpec(*spec)
  File "/usr/local/lib/python2.7/dist-packages/tornado/web.py", line 2774, in __init__
    self.regex = re.compile(pattern)
  File "/usr/lib/python2.7/re.py", line 190, in compile
    return _compile(pattern, flags)
  File "/usr/lib/python2.7/re.py", line 242, in _compile
    raise error, v # invalid expression
sre_constants.error: unbalanced parenthesis
/home/pi/M2More/services.py:53: Warning: Incorrect datetime value: '2015-01- 00:00:00' for column 'time' at row 1
  cur.execute(query)
/home/pi/M2More/services.py:53: Warning: Incorrect datetime value: '2015-01- 23:59:59' for column 'time' at row 1
  cur.execute(query)
ERROR:tornado.application:Uncaught exception GET /statistics/2015-01-02 (192.168.1.35)
HTTPServerRequest(protocol='http', host='192.168.1.50', method='GET', uri='/statistics/2015-01-02', version='HTTP/1.1', remote_ip='192.168.1.35', headers={'Connection': 'keep-alive', 'Accept-Language': 'en-US,en;q=0.8,es;q=0.6', 'Accept-Encoding': 'gzip, deflate, sdch', 'Cookie': '__utma=90629722.1889644263.1420119736.1420119736.1420119736.1; __utmz=90629722.1420119736.1.1.utmcsr=(direct)|utmccn=(direct)|utmcmd=(none)', 'Host': '192.168.1.50', 'Accept': 'text/html,application/xhtml+xml,application/xml;q=0.9,image/webp,*/*;q=0.8', 'User-Agent': 'Mozilla/5.0 (Windows NT 6.1) AppleWebKit/537.36 (KHTML, like Gecko) Chrome/39.0.2171.95 Safari/537.36'})
Traceback (most recent call last):
  File "/usr/local/lib/python2.7/dist-packages/tornado/web.py", line 1332, in _execute
    result = method(*self.path_args, **self.path_kwargs)
  File "/home/pi/M2More/services.py", line 73, in get
    ["ONE", "ONE", "ONE"])
  File "/home/pi/M2More/services.py", line 58, in query_DB
    cur.execute(query)
  File "/usr/lib/python2.7/dist-packages/MySQLdb/cursors.py", line 174, in execute
    self.errorhandler(self, exc, value)
  File "/usr/lib/python2.7/dist-packages/MySQLdb/connections.py", line 36, in defaulterrorhandler
    raise errorclass, errorvalue
ProgrammingError: (1064, "You have an error in your SQL syntax; check the manual that corresponds to your MySQL server version for the right syntax to use near 'between '2015-01-02 00:00:00' and '2015-01-02 23:59:59'' at line 1")
ERROR:tornado.access:500 GET /statistics/2015-01-02 (192.168.1.35) 36.74ms
  File "/home/pi/M2More/services.py", line 75
    json_dict = dict_to_json(dict, records_number = rows_list[0][0])) 
                                                                    ^
SyntaxError: invalid syntax
  File "/home/pi/M2More/services.py", line 75
    json_dict = dict_to_json(dict, records_number = rows_list[0][0])) 
                                                                    ^
SyntaxError: invalid syntax
  File "/home/pi/M2More/services.py", line 75
    json_dict = dict_to_json(dict, records_number = rows_list[0][0])) 
                                                                    ^
SyntaxError: invalid syntax
  File "/home/pi/M2More/services.py", line 75
    json_dict = dict_to_json(dict, records_number = rows_list[0][0])) 
                                                                    ^
SyntaxError: invalid syntax
